Workbook
Name Slicer_Category: #N/A
Name Slicer_Product: #N/A
Name Slicer_Region: #N/A
Name Slicer_Region1: #N/A

Sheet Data
A1: Order_ID | B1: Order_Date | C1: Customer_ID | D1: Customer_Name | E1: Region | F1: Category | G1: Product | H1: Quantity | I1: Unit_Price | J1: Discount | K1: Payment_Method | L1: Order_Status | M1: Delivery_Days | N1: Revenue | O1: Discount_Amount | P1: Net_Sales | Q1: Unit_Cost | R1: Total_Cost | S1: Profit | T1: Profit_Margin | U1: Customer_Type | V1: Delivery_Category | W1: Return_Flag | X1: Order_Month
A2: ORD001 | B2: 46027 | C2: C001 | D2: RaviKumar | E2: South | F2: Electronics | G2: Laptop | H2: 2 | I2: 55000 | J2: 0.05 | K2: UPI | L2: Delivered | M2: 3 | N2: =Ecommerce_data[[#This Row],[Quantity]]*Ecommerce_data[[#This Row],[Unit_Price]] -> 110000 | O2: =Ecommerce_data[[#This Row],[Revenue]]*Ecommerce_data[[#This Row],[Discount]] -> 5500 | P2: =Ecommerce_data[[#This Row],[Revenue]]-Ecommerce_data[[#This Row],[Discount_Amount]] -> 104500 | Q2: =VLOOKUP(G2,Calculations!$A$2:$B$9,2,FALSE) -> 40000 | R2: =Ecommerce_data[[#This Row],[Quantity]]*Ecommerce_data[[#This Row],[Unit_Cost]] -> 80000 | S2: =Ecommerce_data[[#This Row],[Net_Sales]]-Ecommerce_data[[#This Row],[Total_Cost]] -> 24500 | T2: =Ecommerce_data[[#This Row],[Profit]]/Ecommerce_data[[#This Row],[Net_Sales]] -> 0.23444976 | U2: =IF(COUNTIF($C$2:C2,C2)=1,"New Customer","Returning Customer") -> New Customer | V2: =IF(M2<=3,"Fast",IF(M2<=5,"Normal","Delayed")) -> Fast | W2: =IF(L2="Returned","Returned",IF(L2="Delivered","Not Returned","Not Returned")) -> Not Returned | X2: =TEXT(B2,"mmm") -> Jan
A3: ORD002 | B3: 46028 | C3: C002 | D3: Sita | E3: North | F3: Furniture | G3: Office Chair | H3: 3 | I3: 8500 | J3: 0.1 | K3: Card | L3: Delivered | M3: 5 | N3: =Ecommerce_data[[#This Row],[Quantity]]*Ecommerce_data[[#This Row],[Unit_Price]] -> 25500 | O3: =Ecommerce_data[[#This Row],[Revenue]]*Ecommerce_data[[#This Row],[Discount]] -> 2550 | P3: =Ecommerce_data[[#This Row],[Revenue]]-Ecommerce_data[[#This Row],[Discount_Amount]] -> 22950 | Q3: =VLOOKUP(G3,Calculations!$A$2:$B$9,2,FALSE) -> 5500 | R3: =Ecommerce_data[[#This Row],[Quantity]]*Ecommerce_data[[#This Row],[Unit_Cost]] -> 16500 | S3: =Ecommerce_data[[#This Row],[Net_Sales]]-Ecommerce_data[[#This Row],[Total_Cost]] -> 6450 | T3: =Ecommerce_data[[#This Row],[Profit]]/Ecommerce_data[[#This Row],[Net_Sales]] -> 0.28104575 | U3: =IF(COUNTIF($C$2:C3,C3)=1,"New Customer","Returning Customer") -> New Customer | V3: =IF(M3<=3,"Fast",IF(M3<=5,"Normal","Delayed")) -> Normal | W3: =IF(L3="Returned","Returned",IF(L3="Delivered","Not Returned","Not Returned")) -> Not Returned | X3: =TEXT(B3,"mmm") -> Jan
A4: ORD003 | B4: 46030 | C4: C003 | D4: Raj | E4: West | F4: Electronics | G4: Monitor | H4: 2 | I4: 12000 | J4: 0.05 | K4: UPI | L4: Delivered | M4: 2 | N4: =Ecommerce_data[[#This Row],[Quantity]]*Ecommerce_data[[#This Row],[Unit_Price]] -> 24000 | O4: =Ecommerce_data[[#This Row],[Revenue]]*Ecommerce_data[[#This Row],[Discount]] -> 1200 | P4: =Ecommerce_data[[#This Row],[Revenue]]-Ecommerce_data[[#This Row],[Discount_Amount]] -> 22800 | Q4: =VLOOKUP(G4,Calculations!$A$2:$B$9,2,FALSE) -> 8000 | R4: =Ecommerce_data[[#This Row],[Quantity]]*Ecommerce_data[[#This Row],[Unit_Cost]] -> 16000 | S4: =Ecommerce_data[[#This Row],[Net_Sales]]-Ecommerce_data[[#This Row],[Total_Cost]] -> 6800 | T4: =Ecommerce_data[[#This Row],[Profit]]/Ecommerce_data[[#This Row],[Net_Sales]] -> 0.29824561 | U4: =IF(COUNTIF($C$2:C4,C4)=1,"New Customer","Returning Customer") -> New Customer | V4: =IF(M4<=3,"Fast",IF(M4<=5,"Normal","Delayed")) -> Fast | W4: =IF(L4="Returned","Returned",IF(L4="Delivered","Not Returned","Not Returned")) -> Not Returned | X4: =TEXT(B4,"mmm") -> Jan
A5: ORD004 | B5: 46032 | C5: C004 | D5: Priya | E5: East | F5: Stationery | G5: Note Book | H5: 20 | I5: 250 | J5: 0 | K5: Cash | L5: Delivered | M5: 4 | N5: =Ecommerce_data[[#This Row],[Quantity]]*Ecommerce_data[[#This Row],[Unit_Price]] -> 5000 | O5: =Ecommerce_data[[#This Row],[Revenue]]*Ecommerce_data[[#This Row],[Discount]] -> 0 | P5: =Ecommerce_data[[#This Row],[Revenue]]-Ecommerce_data[[#This Row],[Discount_Amount]] -> 5000 | Q5: =VLOOKUP(G5,Calculations!$A$2:$B$9,2,FALSE) -> 120 | R5: =Ecommerce_data[[#This Row],[Quantity]]*Ecommerce_data[[#This Row],[Unit_Cost]] -> 2400 | S5: =Ecommerce_data[[#This Row],[Net_Sales]]-Ecommerce_data[[#This Row],[Total_Cost]] -> 2600 | T5: =Ecommerce_data[[#This Row],[Profit]]/Ecommerce_data[[#This Row],[Net_Sales]] -> 0.52 | U5: =IF(COUNTIF($C$2:C5,C5)=1,"New Customer","Returning Customer") -> New Customer | V5: =IF(M5<=3,"Fast",IF(M5<=5,"Normal","Delayed")) -> Normal | W5: =IF(L5="Returned","Returned",IF(L5="Delivered","Not Returned","Not Returned")) -> Not Returned | X5: =TEXT(B5,"mmm") -> Jan
A6: ORD005 | B6: 46034 | C6: C005 | D6: Ravi | E6: South | F6: Electronics | G6: Key Board | H6: 4 | I6: 1500 | J6: 0.05 | K6: UPI | L6: Delivered | M6: 3 | N6: =Ecommerce_data[[#This Row],[Quantity]]*Ecommerce_data[[#This Row],[Unit_Price]] -> 6000 | O6: =Ecommerce_data[[#This Row],[Revenue]]*Ecommerce_data[[#This Row],[Discount]] -> 300 | P6: =Ecommerce_data[[#This Row],[Revenue]]-Ecommerce_data[[#This Row],[Discount_Amount]] -> 5700 | Q6: =VLOOKUP(G6,Calculations!$A$2:$B$9,2,FALSE) -> 900 | R6: =Ecommerce_data[[#This Row],[Quantity]]*Ecommerce_data[[#This Row],[Unit_Cost]] -> 3600 | S6: =Ecommerce_data[[#This Row],[Net_Sales]]-Ecommerce_data[[#This Row],[Total_Cost]] -> 2100 | T6: =Ecommerce_data[[#This Row],[Profit]]/Ecommerce_data[[#This Row],[Net_Sales]] -> 0.36842105 | U6: =IF(COUNTIF($C$2:C6,C6)=1,"New Customer","Returning Customer") -> New Customer | V6: =IF(M6<=3,"Fast",IF(M6<=5,"Normal","Delayed")) -> Fast | W6: =IF(L6="Returned","Returned",IF(L6="Delivered","Not Returned","Not Returned")) -> Not Returned | X6: =TEXT(B6,"mmm") -> Jan
A7: ORD006 | B7: 46037 | C7: C006 | D7: Anita | E7: North | F7: Furniture | G7: Desk | H7: 1 | I7: 25000 | J7: 0.08 | K7: Card | L7: Delivered | M7: 6 | N7: =Ecommerce_data[[#This Row],[Quantity]]*Ecommerce_data[[#This Row],[Unit_Price]] -> 25000 | O7: =Ecommerce_data[[#This Row],[Revenue]]*Ecommerce_data[[#This Row],[Discount]] -> 2000 | P7: =Ecommerce_data[[#This Row],[Revenue]]-Ecommerce_data[[#This Row],[Discount_Amount]] -> 23000 | Q7: =VLOOKUP(G7,Calculations!$A$2:$B$9,2,FALSE) -> 17000 | R7: =Ecommerce_data[[#This Row],[Quantity]]*Ecommerce_data[[#This Row],[Unit_Cost]] -> 17000 | S7: =Ecommerce_data[[#This Row],[Net_Sales]]-Ecommerce_data[[#This Row],[Total_Cost]] -> 6000 | T7: =Ecommerce_data[[#This Row],[Profit]]/Ecommerce_data[[#This Row],[Net_Sales]] -> 0.26086957 | U7: =IF(COUNTIF($C$2:C7,C7)=1,"New Customer","Returning Customer") -> New Customer | V7: =IF(M7<=3,"Fast",IF(M7<=5,"Normal","Delayed")) -> Delayed | W7: =IF(L7="Returned","Returned",IF(L7="Delivered","Not Returned","Not Returned")) -> Not Returned | X7: =TEXT(B7,"mmm") -> Jan
A8: ORD007 | B8: 46040 | C8: C007 | D8: Kiran | E8: West | F8: Electronics | G8: Mouse | H8: 5 | I8: 800 | J8: 0 | K8: UPI | L8: Delivered | M8: 2 | N8: =Ecommerce_data[[#This Row],[Quantity]]*Ecommerce_data[[#This Row],[Unit_Price]] -> 4000 | O8: =Ecommerce_data[[#This Row],[Revenue]]*Ecommerce_data[[#This Row],[Discount]] -> 0 | P8: =Ecommerce_data[[#This Row],[Revenue]]-Ecommerce_data[[#This Row],[Discount_Amount]] -> 4000 | Q8: =VLOOKUP(G8,Calculations!$A$2:$B$9,2,FALSE) -> 450 | R8: =Ecommerce_data[[#This Row],[Quantity]]*Ecommerce_data[[#This Row],[Unit_Cost]] -> 2250 | S8: =Ecommerce_data[[#This Row],[Net_Sales]]-Ecommerce_data[[#This Row],[Total_Cost]] -> 1750 | T8: =Ecommerce_data[[#This Row],[Profit]]/Ecommerce_data[[#This Row],[Net_Sales]] -> 0.4375 | U8: =IF(COUNTIF($C$2:C8,C8)=1,"New Customer","Returning Customer") -> New Customer | V8: =IF(M8<=3,"Fast",IF(M8<=5,"Normal","Delayed")) -> Fast | W8: =IF(L8="Returned","Returned",IF(L8="Delivered","Not Returned","Not Returned")) -> Not Returned | X8: =TEXT(B8,"mmm") -> Jan
A9: ORD008 | B9: 46042 | C9: C008 | D9: Arjun | E9: East | F9: Stationery | G9: Printer Paper | H9: 10 | I9: 450 | J9: 0.05 | K9: Cash | L9: Delivered | M9: 4 | N9: =Ecommerce_data[[#This Row],[Quantity]]*Ecommerce_data[[#This Row],[Unit_Price]] -> 4500 | O9: =Ecommerce_data[[#This Row],[Revenue]]*Ecommerce_data[[#This Row],[Discount]] -> 225 | P9: =Ecommerce_data[[#This Row],[Revenue]]-Ecommerce_data[[#This Row],[Discount_Amount]] -> 4275 | Q9: =VLOOKUP(G9,Calculations!$A$2:$B$9,2,FALSE) -> 250 | R9: =Ecommerce_data[[#This Row],[Quantity]]*Ecommerce_data[[#This Row],[Unit_Cost]] -> 2500 | S9: =Ecommerce_data[[#This Row],[Net_Sales]]-Ecommerce_data[[#This Row],[Total_Cost]] -> 1775 | T9: =Ecommerce_data[[#This Row],[Profit]]/Ecommerce_data[[#This Row],[Net_Sales]] -> 0.41520468 | U9: =IF(COUNTIF($C$2:C9,C9)=1,"New Customer","Returning Customer") -> New Customer | V9: =IF(M9<=3,"Fast",IF(M9<=5,"Normal","Delayed")) -> Normal | W9: =IF(L9="Returned","Returned",IF(L9="Delivered","Not Returned","Not Returned")) -> Not Returned | X9: =TEXT(B9,"mmm") -> Jan
A10: ORD009 | B10: 46044 | C10: C009 | D10: Meena | E10: South | F10: Electronics | G10: Laptop | H10: 1 | I10: 55000 | J10: 0.1 | K10: Card | L10: Delivered | M10: 7 | N10: =Ecommerce_data[[#This Row],[Quantity]]*Ecommerce_data[[#This Row],[Unit_Price]] -> 55000 | O10: =Ecommerce_data[[#This Row],[Revenue]]*Ecommerce_data[[#This Row],[Discount]] -> 5500 | P10: =Ecommerce_data[[#This Row],[Revenue]]-Ecommerce_data[[#This Row],[Discount_Amount]] -> 49500 | Q10: =VLOOKUP(G10,Calculations!$A$2:$B$9,2,FALSE) -> 40000 | R10: =Ecommerce_data[[#This Row],[Quantity]]*Ecommerce_data[[#This Row],[Unit_Cost]] -> 40000 | S10: =Ecommerce_data[[#This Row],[Net_Sales]]-Ecommerce_data[[#This Row],[Total_Cost]] -> 9500 | T10: =Ecommerce_data[[#This Row],[Profit]]/Ecommerce_data[[#This Row],[Net_Sales]] -> 0.19191919 | U10: =IF(COUNTIF($C$2:C10,C10)=1,"New Customer","Returning Customer") -> New Customer | V10: =IF(M10<=3,"Fast",IF(M10<=5,"Normal","Delayed")) -> Delayed | W10: =IF(L10="Returned","Returned",IF(L10="Delivered","Not Returned","Not Returned")) -> Not Returned | X10: =TEXT(B10,"mmm") -> Jan
A11: ORD010 | B11: 46047 | C11: C010 | D11: Ram | E11: North | F11: Furniture | G11: Office Chair | H11: 2 | I11: 8500 | J11: 0.05 | K11: upi | L11: Delivered | M11: 5 | N11: =Ecommerce_data[[#This Row],[Quantity]]*Ecommerce_data[[#This Row],[Unit_Price]] -> 17000 | O11: =Ecommerce_data[[#This Row],[Revenue]]*Ecommerce_data[[#This Row],[Discount]] -> 850 | P11: =Ecommerce_data[[#This Row],[Revenue]]-Ecommerce_data[[#This Row],[Discount_Amount]] -> 16150 | Q11: =VLOOKUP(G11,Calculations!$A$2:$B$9,2,FALSE) -> 5500 | R11: =Ecommerce_data[[#This Row],[Quantity]]*Ecommerce_data[[#This Row],[Unit_Cost]] -> 11000 | S11: =Ecommerce_data[[#This Row],[Net_Sales]]-Ecommerce_data[[#This Row],[Total_Cost]] -> 5150 | T11: =Ecommerce_data[[#This Row],[Profit]]/Ecommerce_data[[#This Row],[Net_Sales]] -> 0.31888545 | U11: =IF(COUNTIF($C$2:C11,C11)=1,"New Customer","Returning Customer") -> New Customer | V11: =IF(M11<=3,"Fast",IF(M11<=5,"Normal","Delayed")) -> Normal | W11: =IF(L11="Returned","Returned",IF(L11="Delivered","Not Returned","Not Returned")) -> Not Returned | X11: =TEXT(B11,"mmm") -> Jan
A12: ORD011 | B12: 46050 | C12: C001 | D12: Ravikumar | E12: South | F12: Electronics | G12: Monitor | H12: 3 | I12: 12000 | J12: 0.05 | K12: upi | L12: Delivered | M12: 3 | N12: =Ecommerce_data[[#This Row],[Quantity]]*Ecommerce_data[[#This Row],[Unit_Price]] -> 36000 | O12: =Ecommerce_data[[#This Row],[Revenue]]*Ecommerce_data[[#This Row],[Discount]] -> 1800 | P12: =Ecommerce_data[[#This Row],[Revenue]]-Ecommerce_data[[#This Row],[Discount_Amount]] -> 34200 | Q12: =VLOOKUP(G12,Calculations!$A$2:$B$9,2,FALSE) -> 8000 | R12: =Ecommerce_data[[#This Row],[Quantity]]*Ecommerce_data[[#This Row],[Unit_Cost]] -> 24000 | S12: =Ecommerce_data[[#This Row],[Net_Sales]]-Ecommerce_data[[#This Row],[Total_Cost]] -> 10200 | T12: =Ecommerce_data[[#This Row],[Profit]]/Ecommerce_data[[#This Row],[Net_Sales]] -> 0.29824561 | U12: =IF(COUNTIF($C$2:C12,C12)=1,"New Customer","Returning Customer") -> Returning Customer | V12: =IF(M12<=3,"Fast",IF(M12<=5,"Normal","Delayed")) -> Fast | W12: =IF(L12="Returned","Returned",IF(L12="Delivered","Not Returned","Not Returned")) -> Not Returned | X12: =TEXT(B12,"mmm") -> Jan
A13: ORD012 | B13: 46052 | C13: C002 | D13: Sita | E13: North | F13: Stationery | G13: Note Book | H13: 30 | I13: 250 | J13: 0.1 | K13: Card | L13: Delivered | M13: 4 | N13: =Ecommerce_data[[#This Row],[Quantity]]*Ecommerce_data[[#This Row],[Unit_Price]] -> 7500 | O13: =Ecommerce_data[[#This Row],[Revenue]]*Ecommerce_data[[#This Row],[Discount]] -> 750 | P13: =Ecommerce_data[[#This Row],[Revenue]]-Ecommerce_data[[#This Row],[Discount_Amount]] -> 6750 | Q13: =VLOOKUP(G13,Calculations!$A$2:$B$9,2,FALSE) -> 120 | R13: =Ecommerce_data[[#This Row],[Quantity]]*Ecommerce_data[[#This Row],[Unit_Cost]] -> 3600 | S13: =Ecommerce_data[[#This Row],[Net_Sales]]-Ecommerce_data[[#This Row],[Total_Cost]] -> 3150 | T13: =Ecommerce_data[[#This Row],[Profit]]/Ecommerce_data[[#This Row],[Net_Sales]] -> 0.46666667 | U13: =IF(COUNTIF($C$2:C13,C13)=1,"New Customer","Returning Customer") -> Returning Customer | V13: =IF(M13<=3,"Fast",IF(M13<=5,"Normal","Delayed")) -> Normal | W13: =IF(L13="Returned","Returned",IF(L13="Delivered","Not Returned","Not Returned")) -> Not Returned | X13: =TEXT(B13,"mmm") -> Jan
... A61: ORD060 | B61: 46152 | C61: C018 | D61: Manoj | E61: East | F61: Furniture | G61: Office Chair | H61: 4 | I61: 8500 | J61: 0.1 | K61: Card | L61: Delivered | M61: 7 | N61: =Ecommerce_data[[#This Row],[Quantity]]*Ecommerce_data[[#This Row],[Unit_Price]] -> 34000 | O61: =Ecommerce_data[[#This Row],[Revenue]]*Ecommerce_data[[#This Row],[Discount]] -> 3400 | P61: =Ecommerce_data[[#This Row],[Revenue]]-Ecommerce_data[[#This Row],[Discount_Amount]] -> 30600 | Q61: =VLOOKUP(G61,Calculations!$A$2:$B$9,2,FALSE) -> 5500 | R61: =Ecommerce_data[[#This Row],[Quantity]]*Ecommerce_data[[#This Row],[Unit_Cost]] -> 22000 | S61: =Ecommerce_data[[#This Row],[Net_Sales]]-Ecommerce_data[[#This Row],[Total_Cost]] -> 8600 | T61: =Ecommerce_data[[#This Row],[Profit]]/Ecommerce_data[[#This Row],[Net_Sales]] -> 0.28104575 | U61: =IF(COUNTIF($C$2:C61,C61)=1,"New Customer","Returning Customer") -> Returning Customer | V61: =IF(M61<=3,"Fast",IF(M61<=5,"Normal","Delayed")) -> Delayed | W61: =IF(L61="Returned","Returned",IF(L61="Delivered","Not Returned","Not Returned")) -> Not Returned | X61: =TEXT(B61,"mmm") -> May

Sheet Calculations
A1: Product | B1: Unit_Cost
A2: Laptop | B2: 40000
A3: Monitor | B3: 8000
A4: Key Board | B4: 900
A5: Mouse | B5: 450
A6: Desk | B6: 17000
A7: Office Chair | B7: 5500
A8: Note Book | B8: 120
A9: Printer Paper | B9: 250

Sheet Analysis
A1: KPI | B1: Value | D1: PROFIT ANALYSIS | G1: CUSTOMER ANALYSIS | K1: OPERATION ANALYSIS
A2: Total Revenue | B2: =SUM(Data!N2:N61) -> 1842000 | D2: profit by region | G2: new vs returning customer | K2: order_status
A3: Total Discount | B3: =SUM(Data!O2:O61) -> 124382.5 | D3: Region | E3: Sum of Profit | G3: Customer_Type | H3: Count of Order_ID | K3: Order_Status | L3: Count of Order_ID
A4: Total Net Sales | B4: =SUM(Data!P2:P61) -> 1717617.5 | D4: East | E4: 73550 | G4: New Customer | H4: 20 | K4: Cancelled | L4: 1
A5: Total Cost | B5: =SUM(Data!R2:R61) -> 1241000 | D5: North | E5: 109500 | G5: Returning Customer | H5: 40 | K5: Delivered | L5: 57
A6: Total Profit | B6: =SUM(Data!S2:S61) -> 476617.5 | D6: South | E6: 149637.5 | G6: Grand Total | H6: 60 | K6: Returned | L6: 2
A7: Profit _Margin | B7: =B6/B4 -> 0.27748757 | D7: West | E7: 143930 | K7: Grand Total | L7: 60
A8: Total Orders | B8: =COUNTA(Data!A2:A61) -> 60 | D8: Grand Total | E8: 476617.5 | H8: net sales by customer
A9: Average Order Value | B9: =B4/B8 -> 28626.958 | H9: Customer_Name | I9: Sum of Net_Sales | K9: delivery category
A10: Average Delivery Days | B10: =AVERAGE(Data!M2:M61) -> 4.1166667 | D10: profit by category | H10: Amit | I10: 105325 | K10: Delivery_Category | L10: Count of Order_ID
A11: Return Rate | B11: =COUNTIF(Data!W2:W61,"Returned")/COUNTA(Data!A2:A61) -> 0.033333333 | D11: Category | E11: Sum of Profit | H11: Anita | I11: 73640 | K11: Delayed | L11: 14
D12: Electronics | E12: 287355 | H12: Arjun | I12: 36625 | K12: Fast | L12: 24
D13: Furniture | E13: 113750 | H13: Deepa | I13: 108600 | K13: Normal | L13: 22
A14: SALES ANALYSIS | D14: Stationery | E14: 75512.5 | H14: Divya | I14: 138920 | K14: Grand Total | L14: 60
A15: net sales by region | D15: Grand Total | E15: 476617.5 | H15: Kiran | I15: 55760
A16: Region | B16: Sum of Net_Sales | H16: Manoj | I16: 77300 | K16: Average Delivery Days by Region
A17: East | B17: 224550 | D17: profit by product | H17: Meena | I17: 135950 | K17: Region | L17: Average of Delivery_Days
A18: North | B18: 341150 | D18: Product | E18: Sum of Profit | H18: Neha | I18: 110900 | K18: East | L18: 4.75
A19: South | B19: 576237.5 | D19: Desk | E19: 61750 | H19: Pooja | I19: 42150 | K19: North | L19: 5.125
A20: West | B20: 575680 | D20: Key Board | E20: 21075 | H20: Priya | I20: 62500 | K20: South | L20: 3.4444444
A21: Grand Total | B21: 1717617.5 | D21: Laptop | E21: 156100 | H21: Raj | I21: 161500 | K21: West | L21: 3.2857143
D22: Monitor | E22: 93080 | H22: Ram | I22: 48610 | K22: Grand Total | L22: 4.1166667
A23: net sales by category | D23: Mouse | E23: 17100 | H23: Ravi | I23: 113250
A24: Category | B24: Sum of Net_Sales | D24: Note Book | E24: 31475 | H24: RaviKumar | I24: 168625 | K24: Return Rate by Product
A25: Electronics | B25: 1136955 | D25: Office Chair | E25: 52000 | H25: Sanjay | I25: 78500 | K25: Count of Order_ID | L25: Order_Status
A26: Furniture | B26: 410250 | D26: Printer Paper | E26: 44037.5 | H26: Sita | I26: 60300 | K26: Product | L26: Cancelled | M26: Delivered | N26: Returned | O26: Grand Total
A27: Stationery | B27: 170412.5 | D27: Grand Total | E27: 476617.5 | H27: Swathi | I27: 53275 | K27: Desk | L27: 1 | M27: 6 | O27: 7
A28: Grand Total | B28: 1717617.5 | H28: Varun | I28: 37762.5 | K28: Key Board | M28: 5 | N28: 1 | O28: 6
D29: profit_margin by category | H29: Vikram | I29: 48125 | K29: Laptop | M29: 10 | O29: 10
A30: net sales by product | D30: Category | E30: Sum of Profit | F30: Sum of Net_Sales | G30: Profit_Margin | H30: Grand Total | I30: 1717617.5 | K30: Monitor | M30: 10 | O30: 10
A31: Product | B31: Sum of Net_Sales | D31: Electronics | E31: 287355 | F31: 1136955 | G31: =E31/F31 -> 0.25274087 | K31: Mouse | M31: 5 | O31: 5
A32: Desk | B32: 231750 | D32: Furniture | E32: 113750 | F32: 410250 | G32: =E32/F32 -> 0.27726996 | H32: profit by customer | K32: Note Book | M32: 7 | O32: 7
A33: Key Board | B33: 56175 | D33: Stationery | E33: 75512.5 | F33: 170412.5 | G33: =E33/F33 -> 0.44311597 | H33: Customer_Name | I33: Sum of Net_Sales | K33: Office Chair | M33: 7 | N33: 1 | O33: 8
A34: Laptop | B34: 716100 | D34: Grand Total | E34: 476617.5 | F34: 1717617.5 | G34: =E34/F34 -> 0.27748757 | H34: Amit | I34: 105325 | K34: Printer Paper | M34: 7 | O34: 7
A35: Monitor | B35: 325080 | H35: Anita | I35: 73640 | K35: Grand Total | L35: 1 | M35: 57 | N35: 2 | O35: 60
A36: Mouse | B36: 39600 | H36: Arjun | I36: 36625
A37: Note Book | B37: 63875 | H37: Deepa | I37: 108600
A38: Office Chair | B38: 178500 | H38: Divya | I38: 138920
A39: Printer Paper | B39: 106537.5 | H39: Kiran | I39: 55760
A40: Grand Total | B40: 1717617.5 | H40: Manoj | I40: 77300
...

Sheet Dashboard
A1: E-COMMERCE SALES & OPERATIONS DASHBOARD
A3: TOTAL REVENUE | C3: TOTAL DISCOUNT | E3: TOTAL NET SALES | G3: TOTAL COST | I3: TOTAL PROFIT
A4: =Analysis!B2 -> 1842000 | C4: =Analysis!B3 -> 124382.5 | E4: =Analysis!B4 -> 1717617.5 | G4: =Analysis!B5 -> 1241000 | I4: =Analysis!B6 -> 476617.5
A6: PROFIT_MARGIN | C6: TOTAL ORDERS | E6: AVERAGE ORDER VALUE | G6: AVERAGE DELIVERY DAYS | I6: RETURN RATE
A7: =Analysis!B7 -> 0.27748757 | C7: =Analysis!B8 -> 60 | E7: =Analysis!B9 -> 28626.958 | G7: =Analysis!B10 -> 4.1166667 | I7: =Analysis!B11 -> 0.033333333
A54: E-COMMERCE SALES & OPERATIONS |EXCEL PORFOLIO PROJECT
A55: E-COMMERCE SALES & OPERATIONS ANALYSIS |EXCEL|PIVOT- TABLES|PIVOT- CHARTS|SLICERS
